Workbook

Sheet Empresas
A1: ID_EMPRESA | B1: EMPRESA | C1: INDUSTRIA | D1: WEB | E1: REVENEW | F1: REVENEW USD | G1: EMPLEADOS | H1: PROVINCIA | I1: IS | J1: SITUACION | K1: COMENTARIOS | L1: AM | M1: N° DE OPORTUNIDAD | N1: STATUS | O1: MONTO COTIZADO
A2: =_xlfn.CONCAT("E",TEXT(ROW()-1,"000")) -> E001 | B2: Godoy S.R.L. | C2: Goverment | D2: https://www.empresa-ejemplo.com | E2: SIN DATOS | F2: SIN DATOS | G2: 200-500 | H2: Mendoza | I2: AM2 | J2: Prospecting
A3: =_xlfn.CONCAT("E",TEXT(ROW()-1,"000")) -> E002 | B3: Gonzalez S.A. | C3: Goverment | D3: https://www.empresa-ejemplo.com | E3: SIN DATOS | F3: SIN DATOS | G3: 1,000-5,000 | H3: Mendoza | I3: AM2 | J3: Prospecting
A4: =_xlfn.CONCAT("E",TEXT(ROW()-1,"000")) -> E003 | B4: Perez Corp | C4: Manufacture | D4: https://www.empresa-ejemplo.com | E4: 50M-100M | F4: 35K - 70K | G4: 200-500 | H4: Mendoza | I4: AM2 | J4: Prospecting
A5: =_xlfn.CONCAT("E",TEXT(ROW()-1,"000")) -> E004 | B5: Diaz Group | C5: Education | D5: https://www.empresa-ejemplo.com | E5: SIN DATOS | F5: SIN DATOS | G5: 1,000-5,000 | H5: Mendoza | I5: AM2 | J5: Prospecting
A6: =_xlfn.CONCAT("E",TEXT(ROW()-1,"000")) -> E005 | B6: Ponce Group | C6: Manufacture | D6: https://www.empresa-ejemplo.com | E6: 250M-500M | F6: 170K - 350K | G6: 1,000-5,000 | H6: Mendoza | I6: AM2 | J6: Prospecting
A7: =_xlfn.CONCAT("E",TEXT(ROW()-1,"000")) -> E006 | B7: Peralta S.A.S. | C7: Education | D7: https://www.empresa-ejemplo.com | E7: SIN DATOS | F7: SIN DATOS | G7: 1,000-5,000 | H7: Mendoza | I7: AM2 | J7: Prospecting
A8: =_xlfn.CONCAT("E",TEXT(ROW()-1,"000")) -> E007 | B8: Paez S.R.L. | C8: Goverment | D8: https://www.empresa-ejemplo.com | E8: SIN DATOS | F8: SIN DATOS | G8: 1,000-5,000 | H8: Mendoza | I8: AM2 | J8: Prospecting
A9: =_xlfn.CONCAT("E",TEXT(ROW()-1,"000")) -> E008 | B9: Rodriguez S.R.L. | C9: Health | D9: https://www.empresa-ejemplo.com | E9: 250M-500M | F9: 170K - 350K | G9: 1,000-5,000 | H9: Mendoza | I9: AM2 | J9: Prospecting
A10: =_xlfn.CONCAT("E",TEXT(ROW()-1,"000")) -> E009 | B10: Flores Internacional | C10: Manufacture | D10: https://www.empresa-ejemplo.com | E10: 50M-100M | F10: 35K - 70K | G10: 200-500 | H10: Mendoza | I10: AM2 | J10: Prospecting
A11: =_xlfn.CONCAT("E",TEXT(ROW()-1,"000")) -> E010 | B11: Gonzalez S.A. | C11: Oil_Gas_Mining | D11: https://www.empresa-ejemplo.com | E11: SIN DATOS | F11: SIN DATOS | G11: 1,000-5,000 | H11: Mendoza | I11: AM2 | J11: Prospecting
A12: =_xlfn.CONCAT("E",TEXT(ROW()-1,"000")) -> E011 | B12: Diaz S.A. | C12: Education | D12: https://www.empresa-ejemplo.com | E12: SIN DATOS | F12: SIN DATOS | G12: 500-1,000 | H12: Mendoza | I12: AM2 | J12: Prospecting
A13: =_xlfn.CONCAT("E",TEXT(ROW()-1,"000")) -> E012 | B13: Gimenez S.R.L. | C13: Education | D13: https://www.empresa-ejemplo.com | E13: SIN DATOS | F13: SIN DATOS | G13: 200-500 | H13: Mendoza | I13: AM2 | J13: Prospecting
... A29: =_xlfn.CONCAT("E",TEXT(ROW()-1,"000")) -> E028 | B29: Gomez Ltda. | C29: Oil_Gas_Mining | D29: https://www.empresa-ejemplo.com | E29: 50M-100M | F29: 35K - 70K | G29: 201 - 500 | H29: Mendoza | I29: AM2 | J29: Prospecting
A30: =_xlfn.CONCAT("E",TEXT(ROW()-1,"000")) -> E029 | B30: Farias S.R.L. | C30: Service_Provider | D30: https://www.empresa-ejemplo.com | E30: 1M-10M | G30: 51 - 200 | H30: Mendoza | I30: AM2 | J30: Prospecting
A31: =_xlfn.CONCAT("E",TEXT(ROW()-1,"000")) -> E030 | B31: Juarez S.R.L. | C31: Energy | D31: https://www.empresa-ejemplo.com | E31: SIN DATOS | F31: SIN DATOS | G31: 201 - 500 | H31: Mendoza | I31: AM2 | J31: Prospecting
A32: =_xlfn.CONCAT("E",TEXT(ROW()-1,"000")) -> E031 | B32: Cordoba Internacional | C32: Health | D32: https://www.empresa-ejemplo.com | E32: 50M-100M | F32: 35K - 70K | G32: 201 - 500 | H32: Mendoza | I32: AM2 | J32: Not Interested | K32: Sin comentarios.
A33: =_xlfn.CONCAT("E",TEXT(ROW()-1,"000")) -> E032 | B33: Ojeda S.R.L. | C33: Manufacture | D33: https://www.empresa-ejemplo.com | E33: 1M-10M | G33: 201 - 500 | H33: Mendoza | I33: AM2 | J33: Prospecting
A34: =_xlfn.CONCAT("E",TEXT(ROW()-1,"000")) -> E033 | B34: Rojas Ltda. | C34: Manufacture | D34: https://www.empresa-ejemplo.com | E34: 50M-100M | F34: 35K - 70K | G34: 201 - 500 | H34: Mendoza | I34: AM2 | J34: Prospecting
A35: =_xlfn.CONCAT("E",TEXT(ROW()-1,"000")) -> E034 | B35: Valdez Ltda. | C35: Health | D35: https://www.empresa-ejemplo.com | E35: SIN DATOS | F35: SIN DATOS | G35: 201 - 500 | H35: Mendoza | I35: AM2 | J35: Prospecting
A36: =_xlfn.CONCAT("E",TEXT(ROW()-1,"000")) -> E035 | B36: Alvarez Corp | C36: Health | D36: https://www.empresa-ejemplo.com | E36: SIN DATOS | F36: SIN DATOS | G36: 500-1,000 | H36: Mendoza | I36: AM2 | J36: Prospecting
A37: =_xlfn.CONCAT("E",TEXT(ROW()-1,"000")) -> E036 | B37: Molina S.A. | C37: Service_Provider | D37: https://www.empresa-ejemplo.com | E37: SIN DATOS | F37: SIN DATOS | G37: 11 - 50 | H37: Mendoza | I37: AM2 | J37: Prospecting
A38: =_xlfn.CONCAT("E",TEXT(ROW()-1,"000")) -> E037 | B38: Rivero Argentina | C38: Health | D38: https://www.empresa-ejemplo.com | E38: SIN DATOS | F38: SIN DATOS | G38: 50-200 | H38: Mendoza | I38: AM2 | J38: Meeting Scheduled
A39: =_xlfn.CONCAT("E",TEXT(ROW()-1,"000")) -> E038 | B39: Rios S.R.L. | C39: Construction | D39: https://www.empresa-ejemplo.com | E39: 250M-500M | G39: 1,000-5,000 | H39: Mendoza | I39: AM2 | J39: Prospecting
A40: =_xlfn.CONCAT("E",TEXT(ROW()-1,"000")) -> E039 | B40: Guzman Internacional | C40: Entertainment | D40: https://www.empresa-ejemplo.com | E40: SIN DATOS | F40: SIN DATOS | G40: 500-1,000 | H40: Mendoza | I40: AM2 | J40: Prospecting
A41: =_xlfn.CONCAT("E",TEXT(ROW()-1,"000")) -> E040 | B41: Silva S.R.L. | C41: Goverment | D41: https://www.empresa-ejemplo.com | E41: SIN DATOS | F41: SIN DATOS | G41: 10,000-100,000 | H41: Cordoba | I41: AM1 | J41: Prospecting | K41: Sin comentarios.
A42: =_xlfn.CONCAT("E",TEXT(ROW()-1,"000")) -> E041 | B42: Vega Corp | C42: Goverment | D42: https://www.empresa-ejemplo.com | E42: SIN DATOS | F42: SIN DATOS | G42: 1,000-5,000 | H42: Cordoba | I42: AM1 | J42: Prospecting | K42: Sin comentarios.
A43: =_xlfn.CONCAT("E",TEXT(ROW()-1,"000")) -> E042 | B43: Gonzalez Ltda. | C43: Goverment | D43: https://www.empresa-ejemplo.com | E43: SIN DATOS | F43: SIN DATOS | G43: 200-500 | H43: Cordoba | I43: AM1 | J43: Not Interested | K43: Sin comentarios.
A44: =_xlfn.CONCAT("E",TEXT(ROW()-1,"000")) -> E043 | B44: Martinez Group | C44: Manufacture | D44: https://www.empresa-ejemplo.com | E44: SIN DATOS | F44: SIN DATOS | G44: 200-500 | H44: Cordoba | I44: AM1 | J44: Prospecting | K44: Sin comentarios.
A45: =_xlfn.CONCAT("E",TEXT(ROW()-1,"000")) -> E044 | B45: Garcia S.R.L. | C45: Oil_Gas_Mining | D45: https://www.empresa-ejemplo.com | E45: 5M-10M | G45: 1,000-5,000 | H45: Neuquen | I45: AM1 | J45: Prospecting | K45: Sin comentarios.
A46: =_xlfn.CONCAT("E",TEXT(ROW()-1,"000")) -> E045 | B46: Rodriguez S.A. | C46: Oil_Gas_Mining | D46: https://www.empresa-ejemplo.com | E46: 250M-500M | G46: 1,000-5,000 | H46: Neuquen | I46: AM1 | J46: Not Interested | K46: Sin comentarios.
A47: =_xlfn.CONCAT("E",TEXT(ROW()-1,"000")) -> E046 | B47: Martinez Group | C47: Transport_Logistics | D47: https://www.empresa-ejemplo.com | E47: 100M-250M | G47: 1,000-5,000 | H47: Neuquen | I47: AM1 | J47: Not Interested | K47: Sin comentarios.
A48: =_xlfn.CONCAT("E",TEXT(ROW()-1,"000")) -> E047 | B48: Gomez Corp | C48: Banking | D48: https://www.empresa-ejemplo.com | E48: SIN DATOS | G48: 1,000-5,000 | H48: Neuquen | I48: AM1 | J48: Meeting Scheduled | K48: Sin comentarios. | L48: AM4 | N48: Sales Assigned
A49: =_xlfn.CONCAT("E",TEXT(ROW()-1,"000")) -> E048 | B49: Garcia S.R.L. | C49: Service_Provider | D49: https://www.empresa-ejemplo.com | E49: 50M-100M | F49: 35K - 70K | G49: 200-500 | H49: Neuquen | I49: AM1 | J49: Prospecting | K49: Sin comentarios.
A50: =_xlfn.CONCAT("E",TEXT(ROW()-1,"000")) -> E049 | B50: Godoy Group | C50: Goverment | D50: https://www.empresa-ejemplo.com | E50: SIN DATOS | G50: S/D | H50: Neuquen | I50: AM1 | J50: Meeting Scheduled | K50: Sin comentarios.
A51: =_xlfn.CONCAT("E",TEXT(ROW()-1,"000")) -> E050 | B51: Torres S.R.L. | C51: Entertainment | D51: https://www.empresa-ejemplo.com | E51: 100M-250M | G51: 500-1,000 | H51: Neuquen | I51: AM1 | J51: Meeting Scheduled | K51: Sin comentarios. | L51: AM4 | N51: Sales Assigned
A52: =_xlfn.CONCAT("E",TEXT(ROW()-1,"000")) -> E051 | B52: Torres Internacional | C52: Construction | D52: https://www.empresa-ejemplo.com | E52: 250M-500M | G52: 1,000-5,000 | H52: Neuquen | I52: AM1 | J52: Prospecting | K52: Sin comentarios.
A53: =_xlfn.CONCAT("E",TEXT(ROW()-1,"000")) -> E052 | B53: Diaz Corp | C53: Oil_Gas_Mining | D53: https://www.empresa-ejemplo.com | E53: 100M-250M | G53: 500-1,000 | H53: Neuquen | I53: AM1 | J53: Not Interested | K53: Sin comentarios. | L53: LM
A54: =_xlfn.CONCAT("E",TEXT(ROW()-1,"000")) -> E053 | B54: Perez Argentina | C54: Transport_Logistics | D54: https://www.empresa-ejemplo.com | E54: 50M-100M | F54: 35K - 70K | G54: 1,000-5,000 | H54: Neuquen | I54: AM1 | J54: Prospecting | K54: Sin comentarios.
A55: =_xlfn.CONCAT("E",TEXT(ROW()-1,"000")) -> E054 | B55: Maidana Ltda. | C55: Manufacture | D55: https://www.empresa-ejemplo.com | E55: 500M-1B | G55: 10,000-100,000 | H55: Cordoba | I55: AM1 | J55: Prospecting | K55: Sin comentarios.
...

Sheet Contactos
A1: ID Contacto | B1: ID_Empresa | C1: EMPRESA | D1: NOMBRE | E1: PUESTO | F1: EMAIL | G1: TELEFONO | H1: LINKEDIN | I1: COMENTARIO | J1: IC N° | K1: SALESFORCE STATUS
A2: =_xlfn.CONCAT("C",TEXT(ROW()-1,"000")) -> C001 | B2: E001 | C2: Godoy S.R.L. | D2: Thiago Benjamin Maia Gomez | E2: Jefa de Administracion de Sistemas | F2: thiago.ben@godoysrl.com.ar | G2: +54 9 92 906-2771 | H2: https://www.linkedin.com/in/thiago-benjamin-maia-gomez-58 | I2: Contacto en proceso. | J2: 2
A3: =_xlfn.CONCAT("C",TEXT(ROW()-1,"000")) -> C002 | B3: E001 | C3: Godoy S.R.L. | D3: Alma Mia Diaz Maldonado | E3: Jefa de Informatica y Comunicaciones | F3: alma.mia.d@godoysrl.com.ar | G3: +54 9 30 979-8711 | H3: https://www.linkedin.com/in/alma-mia-diaz-maldonado-38 | I3: Contacto en proceso. | J3: 6
A4: =_xlfn.CONCAT("C",TEXT(ROW()-1,"000")) -> C003 | B4: E001 | C4: Godoy S.R.L. | D4: Lautaro Paz | E4: Encargado de Compras y Contrataciones | F4: lautaro.pa@godoysrl.com.ar | G4: +54 9 113 936-8541 | H4: https://www.linkedin.com/in/lautaro-paz-54 | I4: Contacto en proceso. | J4: 3
A5: =_xlfn.CONCAT("C",TEXT(ROW()-1,"000")) -> C004 | B5: E001 | C5: Godoy S.R.L. | D5: Delfina Milagros Ruiz | E5: Jefe de Desarrollo de Sistemas | F5: delfina.mi@godoysrl.com.ar | G5: +54 9 167 940-4728 | H5: https://www.linkedin.com/in/delfina-milagros-ruiz-38 | I5: Contacto en proceso. | J5: 3
A6: =_xlfn.CONCAT("C",TEXT(ROW()-1,"000")) -> C005 | B6: E002 | C6: Gonzalez S.A. | D6: Santino Ezequiel Nahiara Garcia Moreno | E6: Administrador IT | F6: santino.ez@gonzalezsa.com.ar | H6: https://www.linkedin.com/in/santino-ezequiel-nahiara-garcia-moreno-13 | I6: Contacto en proceso. | J6: 3
A7: =_xlfn.CONCAT("C",TEXT(ROW()-1,"000")) -> C006 | B7: E002 | C7: Gonzalez S.A. | D7: Agostina Farias | E7: Auxiliar de Laboratorio de Informatica | F7: agostina.f@gonzalezsa.com.ar | H7: https://www.linkedin.com/in/agostina-farias-94 | I7: Contacto en proceso. | J7: 3
A8: =_xlfn.CONCAT("C",TEXT(ROW()-1,"000")) -> C007 | B8: E002 | C8: Gonzalez S.A. | D8: Luisana Juan Ignacio Valdez Lopez | E8: Administrador de red | F8: luisana.ju@gonzalezsa.com.ar | H8: https://www.linkedin.com/in/luisana-juan-ignacio-valdez-lopez-34 | I8: Contacto en proceso. | J8: 1
A9: =_xlfn.CONCAT("C",TEXT(ROW()-1,"000")) -> C008 | B9: E003 | C9: Perez Corp | D9: Martina Matias Romero Caceres | E9: Director de Proyecto | F9: martina.ma@perezcorp.com.ar | H9: https://www.linkedin.com/in/martina-matias-romero-caceres-61 | I9: Contacto en proceso. | J9: 1
A10: =_xlfn.CONCAT("C",TEXT(ROW()-1,"000")) -> C009 | B10: N/A | C10: Benitez Ltda. | D10: Sr(a). Olivia Silva | E10: Technical Operator Master | F10: sr(a)..oli@benitezltd.com.ar | H10: https://www.linkedin.com/in/sr(a).-olivia-silva-45 | I10: Contacto en proceso. | J10: N/A | K10: Unqualified
A11: =_xlfn.CONCAT("C",TEXT(ROW()-1,"000")) -> C010 | B11: N/A | C11: Benitez Ltda. | D11: Martina Lorenzo Gutierrez Cordoba | E11: Gerente de Sistemas | F11: martina.lo@benitezltd.com.ar | G11: +54 9 46 891-5573 | H11: https://www.linkedin.com/in/martina-lorenzo-gutierrez-cordoba-54 | I11: Contacto en proceso. | J11: N/A
A12: =_xlfn.CONCAT("C",TEXT(ROW()-1,"000")) -> C011 | B12: N/A | C12: Benitez Ltda. | D12: Guadalupe Bautista Dominguez | E12: Help Desk IT | H12: https://www.linkedin.com/in/guadalupe-bautista-dominguez-92 | I12: Contacto en proceso. | J12: N/A
A13: =_xlfn.CONCAT("C",TEXT(ROW()-1,"000")) -> C012 | B13: N/A | C13: Benitez Ltda. | D13: Julian Antonella Gomez Mendoza | E13: Responsable de Proyectos | H13: https://www.linkedin.com/in/julian-antonella-gomez-mendoza-75 | I13: Contacto en proceso. | J13: N/A
A14: =_xlfn.CONCAT("C",TEXT(ROW()-1,"000")) -> C013 | B14: N/A | C14: Benitez Ltda. | D14: Dr(a). Vicente Romero | E14: Director de Tecnologia y Operaciones Tecnicas | F14: dr(a)..vic@benitezltd.com.ar | G14: +54 9 215 795-9785 | H14: https://www.linkedin.com/in/dr(a).-vicente-romero-52 | I14: Contacto en proceso. | J14: N/A
A15: =_xlfn.CONCAT("C",TEXT(ROW()-1,"000")) -> C014 | B15: E004 | C15: Diaz Group | D15: Lautaro Benjamin Santiago Dominguez Alvarez | E15: Administrador de Sistemas e Infraestructura de Red | F15: lautaro.be@diazgroup.com.ar | H15: https://www.linkedin.com/in/lautaro-benjamin-santiago-dominguez-alvarez-13 | I15: Contacto en proceso. | J15: 10
A16: =_xlfn.CONCAT("C",TEXT(ROW()-1,"000")) -> C015 | B16: E004 | C16: Diaz Group | D16: Mora Julieta Molina | E16: Director de TI | F16: mora.julie@diazgroup.com.ar | G16: +54 9 70 998-5279 | H16: https://www.linkedin.com/in/mora-julieta-molina-32 | I16: Contacto en proceso. | J16: 1
A17: =_xlfn.CONCAT("C",TEXT(ROW()-1,"000")) -> C016 | B17: E004 | C17: Diaz Group | D17: Julieta Diaz Caceres | E17: Coordinador de Tecnologia | F17: julieta.di@diazgroup.com.ar | G17: +54 9 146 139-2776 | I17: Contacto en proceso.
A18: =_xlfn.CONCAT("C",TEXT(ROW()-1,"000")) -> C017 | B18: =IFERROR(_xlfn.XLOOKUP(C18,Empresas!$B:$B,Empresas!$A:$A),"") -> E040 | C18: Silva S.R.L. | D18: Dr(a). Valentin Benitez | E18: System Admin | F18: dr(a)..val@silvasrl.com.ar | G18: +54 9 233 453-6139 | H18: https://www.linkedin.com/in/dr(a).-valentin-benitez-65 | I18: Contacto en proceso.
A19: =_xlfn.CONCAT("C",TEXT(ROW()-1,"000")) -> C018 | B19: =IFERROR(_xlfn.XLOOKUP(C19,Empresas!$B:$B,Empresas!$A:$A),"") -> E040 | C19: Silva S.R.L. | D19: Bianca Geronimo Campos | E19: Purchasing and Proc Manager | F19: bianca.ger@silvasrl.com.ar | G19: +54 9 272 218-7311 | H19: https://www.linkedin.com/in/bianca-geronimo-campos-83 | I19: Contacto en proceso.
A20: =_xlfn.CONCAT("C",TEXT(ROW()-1,"000")) -> C019 | B20: =IFERROR(_xlfn.XLOOKUP(C20,Empresas!$B:$B,Empresas!$A:$A),"") -> E040 | C20: Silva S.R.L. | D20: Milagros Emilia Dominguez | E20: Technology Advisor | F20: milagros.e@silvasrl.com.ar | G20: +54 9 108 360-1727 | H20: https://www.linkedin.com/in/milagros-emilia-dominguez-65 | I20: Contacto en proceso.
A21: =_xlfn.CONCAT("C",TEXT(ROW()-1,"000")) -> C020 | B21: =IFERROR(_xlfn.XLOOKUP(C21,Empresas!$B:$B,Empresas!$A:$A),"") -> E040 | C21: Silva S.R.L. | D21: Dr(a). Catalina Moyano | E21: IT Infraestructure Director | F21: dr(a)..cat@silvasrl.com.ar | G21: +54 9 11 632-9821 | H21: https://www.linkedin.com/in/dr(a).-catalina-moyano-97 | I21: Contacto en proceso.
A22: =_xlfn.CONCAT("C",TEXT(ROW()-1,"000")) -> C021 | B22: E040 | C22: Silva S.R.L. | D22: Felicitas Francisco Diaz | E22: Subsecretario de Infraestructura | F22: felicitas.@silvasrl.com.ar | G22: +54 9 111 472-8066 | H22: https://www.linkedin.com/in/felicitas-francisco-diaz-18 | I22: Contacto en proceso.
A23: =_xlfn.CONCAT("C",TEXT(ROW()-1,"000")) -> C022 | B23: =IFERROR(_xlfn.XLOOKUP(C23,Empresas!$B:$B,Empresas!$A:$A),"") -> E041 | C23: Vega Corp | D23: Isabella Velazquez Cabrera | E23: Technology Infrastructure Manager | F23: isabella.v@vegacorp.com.ar | G23: +54 9 180 738-6143 | H23: https://www.linkedin.com/in/isabella-velazquez-cabrera-94 | I23: Contacto en proceso. | J23: 6
A24: =_xlfn.CONCAT("C",TEXT(ROW()-1,"000")) -> C023 | B24: =IFERROR(_xlfn.XLOOKUP(C24,Empresas!$B:$B,Empresas!$A:$A),"") -> E041 | C24: Vega Corp | D24: Facundo Cruz Silva | E24: CTO | F24: facundo.cr@vegacorp.com.ar | G24: +54 9 74 837-5920 | H24: https://www.linkedin.com/in/facundo-cruz-silva-74 | I24: Contacto en proceso. | J24: 3
A25: =_xlfn.CONCAT("C",TEXT(ROW()-1,"000")) -> C024 | B25: =IFERROR(_xlfn.XLOOKUP(C25,Empresas!$B:$B,Empresas!$A:$A),"") -> E041 | C25: Vega Corp | D25: Morena Martinez | E25: Jefe de depto de OP | F25: morena.mar@vegacorp.com.ar | G25: +54 9 169 782-7691 | H25: https://www.linkedin.com/in/morena-martinez-51 | I25: Contacto en proceso. | J25: 3
A26: =_xlfn.CONCAT("C",TEXT(ROW()-1,"000")) -> C025 | B26: =IFERROR(_xlfn.XLOOKUP(C26,Empresas!$B:$B,Empresas!$A:$A),"") -> E042 | C26: Gonzalez Ltda. | D26: Uma Guzman Cruz | E26: Coordinador de Administración | F26: uma.guzman@gonzalezlt.com.ar | G26: +54 9 217 813-5844 | H26: https://www.linkedin.com/in/uma-guzman-cruz-80 | I26: Contacto en proceso. | J26: 3
A27: =_xlfn.CONCAT("C",TEXT(ROW()-1,"000")) -> C026 | B27: =IFERROR(_xlfn.XLOOKUP(C27,Empresas!$B:$B,Empresas!$A:$A),"") -> E042 | C27: Gonzalez Ltda. | D27: Delfina Cordoba | E27: Director de OP | F27: delfina.co@gonzalezlt.com.ar | G27: +54 9 76 296-7888 | H27: https://www.linkedin.com/in/delfina-cordoba-95 | I27: Contacto en proceso. | J27: 2
A28: =_xlfn.CONCAT("C",TEXT(ROW()-1,"000")) -> C027 | B28: =IFERROR(_xlfn.XLOOKUP(C28,Empresas!$B:$B,Empresas!$A:$A),"") -> E042 | C28: Gonzalez Ltda. | D28: Dr(a). Isabella Martinez | E28: Director Provincial | F28: dr(a)..isa@gonzalezlt.com.ar | G28: +54 9 205 793-3851 | H28: https://www.linkedin.com/in/dr(a).-isabella-martinez-88 | I28: Contacto en proceso. | J28: 6
A29: =_xlfn.CONCAT("C",TEXT(ROW()-1,"000")) -> C028 | B29: =IFERROR(_xlfn.XLOOKUP(C29,Empresas!$B:$B,Empresas!$A:$A),"") -> E043 | C29: Martinez Group | D29: Facundo Figueroa Carrizo | E29: Managing Partner | F29: facundo.fi@martinezgr.com.ar | G29: +54 9 165 515-9977 | H29: https://www.linkedin.com/in/facundo-figueroa-carrizo-10 | I29: Contacto en proceso. | J29: 5
A30: =_xlfn.CONCAT("C",TEXT(ROW()-1,"000")) -> C029 | B30: E043 | C30: Martinez Group | D30: Dr(a). Maria Guadalupe Paez | F30: dr(a)..mar@martinezgr.com.ar | G30: +54 9 166 393-4443 | I30: Contacto en proceso. | J30: 4
A31: =_xlfn.CONCAT("C",TEXT(ROW()-1,"000")) -> C030 | B31: =IFERROR(_xlfn.XLOOKUP(C31,Empresas!$B:$B,Empresas!$A:$A),"") -> E043 | C31: Martinez Group | D31: Dr(a). Ludmila Molina | E31: Office Administrator | F31: dr(a)..lud@martinezgr.com.ar | H31: https://www.linkedin.com/in/dr(a).-ludmila-molina-65 | I31: Contacto en proceso. | J31: 4
A32: =_xlfn.CONCAT("C",TEXT(ROW()-1,"000")) -> C031 | B32: E005 | C32: Ponce Group | D32: Maria Emilia Agustin Perez | E32: Coordinador de TI | F32: maria.emil@poncegroup.com.ar | G32: +54 9 175 576-8238 | H32: https://www.linkedin.com/in/maria-emilia-agustin-perez-66 | I32: Contacto en proceso. | J32: 8
A33: =_xlfn.CONCAT("C",TEXT(ROW()-1,"000")) -> C032 | B33: E005 | C33: Ponce Group | D33: Giuliana Victoria Ramos | E33: Jefe de Compras | F33: giuliana.v@poncegroup.com.ar | G33: +54 9 120 623-8752 | H33: https://www.linkedin.com/in/giuliana-victoria-ramos-31 | I33: Contacto en proceso. | J33: N/A
A34: =_xlfn.CONCAT("C",TEXT(ROW()-1,"000")) -> C033 | B34: E005 | C34: Ponce Group | D34: Lucía Perez | E34: Gerente de Compras | F34: lucía.pere@poncegroup.com.ar | H34: https://www.linkedin.com/in/lucía-perez-94
A35: =_xlfn.CONCAT("C",TEXT(ROW()-1,"000")) -> C034 | B35: E005 | C35: Ponce Group | D35: Luz Milagros Martinez Romero | E35: Administrador de redes | F35: luz.milagr@poncegroup.com.ar | H35: https://www.linkedin.com/in/luz-milagros-martinez-romero-20
A36: =_xlfn.CONCAT("C",TEXT(ROW()-1,"000")) -> C035 | B36: E006 | C36: Peralta S.A.S. | D36: Sr(a). Valentino Martinez | E36: Director de Tecnologia | F36: sr(a)..val@peraltasas.com.ar | G36: +54 9 156 627-6491 | H36: https://www.linkedin.com/in/sr(a).-valentino-martinez-21 | I36: Contacto en proceso.
A37: =_xlfn.CONCAT("C",TEXT(ROW()-1,"000")) -> C036 | B37: E006 | C37: Peralta S.A.S. | D37: Lucia Bautista Ramirez | E37: Director de Compras y Suministros | F37: lucia.baut@peraltasas.com.ar
A38: =_xlfn.CONCAT("C",TEXT(ROW()-1,"000")) -> C037 | B38: E007 | C38: Paez S.R.L. | D38: Dr(a). Ciro Diaz | E38: Director de Tranformacion Digital | F38: dr(a)..cir@paezsrl.com.ar | H38: https://www.linkedin.com/in/dr(a).-ciro-diaz-40
A39: =_xlfn.CONCAT("C",TEXT(ROW()-1,"000")) -> C038 | B39: E007 | C39: Paez S.R.L. | D39: Francesca Vazquez | E39: Jefe de Sistemas | F39: francesca.@paezsrl.com.ar | H39: https://www.linkedin.com/in/francesca-vazquez-96
A40: =_xlfn.CONCAT("C",TEXT(ROW()-1,"000")) -> C039 | B40: E008 | C40: Rodriguez S.R.L. | D40: Jazmín Vazquez Alvarez | E40: Supervisor de Sistemas | F40: jazmín.vaz@rodriguezs.com.ar | H40: https://www.linkedin.com/in/jazmín-vazquez-alvarez-49 | I40: Contacto en proceso.
...

Sheet Hoja2
A1: MES | B1: EMPRESA | C1: AM | D1: COTIZACION | E1: NUMERO DE OPP | F1: COMISION
A2: ENERO | B2: Flores S.R.L. | C2: AM4 | D2: NO
A3: ENERO | B3: Cruz Ltda. | C3: AM5 | D3: SI | E3: BLVI20260158-724540 | F3: 10USD
A4: ENERO | B4: Lopez Internacional | C4: AM4 | D4: EN ESPERA
A5: ENERO | B5: Fernandez Ltda. | C5: AM3 | D5: NO
A6: FEBRERO | B6: Ojeda S.A. | C6: AM4 | D6: NO
A7: FEBRERO | B7: Diaz S.R.L. | C7: AM3 | D7: NO
A8: MARZO | B8: Chavez Corp | C8: AM3 | D8: EN ESPERA
A9: MARZO | B9: Farias Argentina | C9: AM4 | D9: EN ESPERA
A10: MARZO | B10: Gomez Argentina | C10: JLM | D10: MANDO PARTE DEL LISTADO, FALTAN ESPECIFICACIONES
A11: MARZO | B11: Bustos Group | C11: AM4 | D11: EN ESPERA
A12: MARZO | B12: Suarez Ltda. | C12: JLM | D12: EN ESPERA
A13: MARZO | B13: Ortiz Internacional | C13: AM3 | D13: EN ESPERA
A14: MARZO | B14: Benitez Internacional | C14: AM4 | D14: EN ESPERA
A15: MARZO | B15: Cabrera S.A.S. | C15: JLM | D15: EN ESPERA
... A18: MARZO | B18: Guzman Corp | C18: AM4 | D18: REPROGRAMADA PARA VIERNES 27/3
A19: MARZO | B19: Lucero Group | C19: JLM
A20: MARZO | B20: Ojeda S.R.L. | C20: JLM
A23: MES | B23: Paez S.R.L. | C23: AM | D23: COTIZACION | E23: GJUE20256484-432061 | F23: COMISION
A24: ENERO | B24: Suarez Ltda. | C24: AM3 | D24: NO

Sheet LEADS CARGADOS EN SF

Sheet Parametros
A1: Provincias | B1: AM | C1: IS | D1: Situacion | E1: Industria | F1: Revenew | G1: Empleados | H1: Estado_Contrato | I1: Salesforce_Status | J1: Ailen | K1: Franco | L1: Revenew USD
A2: Buenos_Aires | B2: HP | C2: AA | D2: Prospectando | E2: Banca | F2: 1M-10M | G2: 200-500 | H2: Lost | I2: Unqualified | J2: Mendoza | K2: Cordoba | L2: 1K - 7K
A3: La_Pampa | B3: CC | C3: FZ | D3: F/P | E3: Petroleo_Gas_Mineria | F3: 5M-10M | G3: 500-1,000 | H3: Development | I3: Nurture | J3: Santa Fe | K3: Neuquen | L3: 3K - 7K
A4: Catamarca | B4: LM | D4: No interesado | E4: Transporte_Logistica | F4: 10M-50M | G4: 1,000-5,000 | H4: Win | I4: Sales Assigned | L4: 7K - 35K
A5: Jujuy | B5: PE | D5: No contesta | E5: Gobierno | F5: 50M-100M | G5: 5,000-10,000 | I5: Converted | L5: 35K - 70K
A6: San_Juan | D6: Reunion Agendada | E6: Salud | F6: 100M-250M | G6: 10,000-100,000 | L6: 70K - 170K
A7: Cordoba | D7: S/D | E7: Service_Provider | F7: 250M-500M | G7: SIN DATOS | L7: 170K - 350K
A8: Tucuman | D8: Cotizado | E8: Tecnologia | F8: 500M-1B | G8: 50-200 | L8: 350K - 700K
A9: San_Luis | D9: Competencia | E9: Manufactura | F9: 1B-10B | L9: 700K - 7M
A10: Santa_Cruz | E10: Construccion | F10: SIN DATOS | L10: SIN DATOS
A11: Chubut | E11: Entretenimiento
A12: Rio_Negro | E12: Automotriz
A13: Santa_Fe | E13: Energia
A14: Chaco | E14: Educación
A15: Entre_Rios | E15: Retail
A16: Corrientes
A17: Formosa
A18: La_Rioja
A19: Mendoza
A20: Neuquen
A21: Misiones
A22: Salta
A23: Santiago_del_Estero

Sheet EMPRESAS X INDUSTRIA
A3: Cuenta de EMPRESA | B3: EMPLEADOS
A4: INDUSTRIA | B4: 1,000-5,000 | C4: 10,000-100,000 | D4: 11 - 50 | E4: 200-500 | F4: 201 - 500 | G4: 5,000-10,000 | H4: 500-1,000 | I4: 50-200 | J4: 51 - 200 | K4: S/D | L4: (en blanco) | M4: Total general | R4: INDUSTRIA | S4: EMPRESAS POR INDUSTRIA | T4: PROMEDIO EMPLEADOS
A5: Automotriz | B5: 1 | E5: 1 | H5: 2 | M5: 4 | R5: Construccion | S5: 4 | T5: 1000-5000
A6: Banca | B6: 2 | E6: 5 | H6: 2 | I6: 4 | M6: 13 | R6: Educación | S6: 5 | T6: 1000-5000
A7: Construccion | B7: 6 | E7: 6 | H7: 2 | I7: 2 | M7: 16 | R7: Manufactura_Logistica | S7: 16 | T7: 1000-5000
A8: Educación | B8: 3 | E8: 5 | H8: 3 | M8: 11 | R8: Petroleo_Gas_Mineria | S8: 12 | T8: 1000-5000
A9: Energia | B9: 2 | F9: 1 | G9: 1 | H9: 1 | I9: 1 | M9: 6 | R9: Salud | S9: 20 | T9: 1000-5000
A10: Entretenimiento | E10: 5 | H10: 4 | M10: 9 | R10: Transporte_Logistica | S10: 3 | T10: 1000-5000
A11: Gobierno | B11: 8 | C11: 2 | E11: 8 | G11: 2 | H11: 1 | I11: 5 | K11: 1 | L11: 1 | M11: 28 | R11: Retail | S11: 2 | T11: 1000-5000
A12: Manufactura | B12: 10 | C12: 1 | E12: 19 | F12: 2 | H12: 16 | I12: 8 | M12: 56 | R12: Banca | S12: 8 | T12: 200-500
A13: Petroleo_Gas_Mineria | B13: 5 | C13: 2 | E13: 9 | F13: 1 | G13: 1 | H13: 5 | I13: 2 | M13: 25 | R13: Gobierno | S13: 17 | T13: 200-500
A14: Salud | B14: 5 | C14: 1 | E14: 7 | F14: 2 | H14: 8 | I14: 5 | M14: 28 | R14: Manufactura | S14: 19 | T14: 200-500
A15: Service_Provider | B15: 4 | D15: 1 | E15: 19 | G15: 1 | H15: 2 | I15: 8 | J15: 1 | L15: 2 | M15: 38 | R15: Service_Provider | S15: 15 | T15: 200-500
A16: Tecnologia | B16: 1 | E16: 2 | H16: 1 | I16: 10 | M16: 14 | R16: Automotriz | S16: 2 | T16: 500-1000
A17: Transporte_Logistica | B17: 2 | E17: 2 | H17: 2 | I17: 3 | M17: 9 | R17: Energia | S17: 7 | T17: 500-1000
A18: Retail | B18: 3 | E18: 3 | H18: 3 | I18: 2 | M18: 11 | R18: Entretenimiento | S18: 6 | T18: 500-1000
A19: Total general | B19: 52 | C19: 6 | D19: 1 | E19: 91 | F19: 6 | G19: 5 | H19: 52 | I19: 50 | J19: 1 | K19: 1 | L19: 3 | M19: 268 | R19: Tecnologia | S19: 3 | T19: 50-200
L23: IDEA
L24: EMPRESAS QUE MAYOR EMPLEADOS TENGAN, MAYOR PROBABILIDAD DE CONTACTOS, MAYOR PROBABILIDAD DE INFRAESTRUCTURA
L25: BUSCAR LOS MEJORES LOGOS
M33: PETROLEO
M34: MANUFACTURA LOGISTICA
M35: MANUFACTURA
M36: ENERGIA
A45: Cuenta de EMPRESA | B45: EMPLEADOS | P45: INDUSTRIA | Q45: EMPRESAS POR INDUSTRIA | R45: PROMEDIO EMPLEADOS | S45: Columna1
A46: INDUSTRIA | B46: 1,000-5,000 | C46: 10,000-100,000 | D46: 11 - 50 | E46: 200-500 | F46: 201 - 500 | G46: 5,000-10,000 | H46: 500-1,000 | I46: 50-200 | J46: 51 - 200 | K46: S/D | L46: SIN DATOS | M46: Total general | P46: Automotriz | Q46: 5 | R46: 500-1000 | S46: =Q46 & " empresas | " & R46 & " emp" -> 5 empresas | 500-1000 emp
A47: Automotriz | B47: 1 | E47: 1 | H47: 2 | M47: 4 | P47: Banca | Q47: 9 | R47: 500-1000 | S47: =Q47 & " empresas | " & R47 & " emp" -> 9 empresas | 500-1000 emp
A48: Banca | B48: 2 | E48: 5 | H48: 2 | I48: 4 | M48: 13 | P48: Construccion | Q48: 12 | R48: 1000-5000 | S48: =Q48 & " empresas | " & R48 & " emp" -> 12 empresas | 1000-5000 emp
A49: Construccion | B49: 6 | E49: 6 | H49: 2 | I49: 2 | M49: 16 | P49: Educación | Q49: 10 | R49: 1000-5000 | S49: =Q49 & " empresas | " & R49 & " emp" -> 10 empresas | 1000-5000 emp
A50: Educación | B50: 3 | E50: 5 | H50: 3 | M50: 11 | P50: Energia | Q50: 6 | R50: 1000-5000 | S50: =Q50 & " empresas | " & R50 & " emp" -> 6 empresas | 1000-5000 emp
A51: Energia | B51: 2 | F51: 1 | G51: 1 | H51: 1 | I51: 1 | M51: 6 | P51: Entretenimiento | Q51: 10 | R51: 500-1000 | S51: =Q51 & " empresas | " & R51 & " emp" -> 10 empresas | 500-1000 emp
A52: Entretenimiento | E52: 5 | H52: 4 | L52: 1 | M52: 10 | P52: Gobierno | Q52: 30 | R52: 200-500 | S52: =Q52 & " empresas | " & R52 & " emp" -> 30 empresas | 200-500 emp
A53: Gobierno | B53: 8 | C53: 2 | E53: 8 | G53: 2 | H53: 1 | I53: 5 | K53: 1 | L53: 2 | M53: 29 | P53: Manufactura | Q53: 61 | R53: 200-500 | S53: =Q53 & " empresas | " & R53 & " emp" -> 61 empresas | 200-500 emp
A54: Manufactura | B54: 10 | C54: 1 | E54: 19 | F54: 2 | H54: 16 | I54: 8 | L54: 9 | M54: 65 | P54: Petroleo_Gas_Mineria | Q54: 20 | R54: 1000-5000 | S54: =Q54 & " empresas | " & R54 & " emp" -> 20 empresas | 1000-5000 emp
A55: Petroleo_Gas_Mineria | B55: 5 | C55: 2 | E55: 9 | F55: 1 | G55: 1 | H55: 5 | I55: 2 | M55: 25 | P55: Retail | Q55: 7 | R55: 1000-5000 | S55: =Q55 & " empresas | " & R55 & " emp" -> 7 empresas | 1000-5000 emp
A56: Retail | B56: 3 | E56: 3 | H56: 3 | I56: 2 | M56: 11 | P56: Salud | Q56: 28 | R56: 1000-5000 | S56: =Q56 & " empresas | " & R56 & " emp" -> 28 empresas | 1000-5000 emp
A57: Salud | B57: 5 | C57: 1 | E57: 7 | F57: 2 | H57: 8 | I57: 5 | L57: 3 | M57: 31 | P57: Service_Provider | Q57: 31 | R57: 200-500 | S57: =Q57 & " empresas | " & R57 & " emp" -> 31 empresas | 200-500 emp
A58: Service_Provider | B58: 4 | D58: 1 | E58: 19 | G58: 1 | H58: 2 | I58: 8 | J58: 1 | L58: 1 | M58: 37 | P58: Tecnologia | Q58: 12 | R58: 1000-5000 | S58: =Q58 & " empresas | " & R58 & " emp" -> 12 empresas | 1000-5000 emp
A59: Tecnologia | B59: 1 | E59: 2 | H59: 1 | I59: 10 | L59: 1 | M59: 15 | P59: Transporte_Logistica | Q59: 9 | R59: 1000-5000 | S59: =Q59 & " empresas | " & R59 & " emp" -> 9 empresas | 1000-5000 emp
A60: Transporte_Logistica | B60: 2 | E60: 2 | H60: 2 | I60: 3 | M60: 9 | S60: =Q60 & " empresas | " & R60 & " emp" -> empresas | emp
...

Sheet Hoja1
C3: INDUSTRIA | D3: PROMEDIO DE EMPLEADOS
C4: Construccion | D4: 1000 - 5000 empleados
C5: Educación | D5: 1000 - 5000 empleados
C6: Energia | D6: 1000 - 5000 empleados
C7: Transporte y Logistica | D7: 1000 - 5000 empleados
C8: Petroleo,Gas y Mineria | D8: 1000 - 5000 empleados
C9: Retail | D9: 1000 - 5000 empleados
C10: Salud | D10: 1000 - 5000 empleados
C11: Tecnologia | D11: 1000 - 5000 empleados
C12: Banca | D12: 500 - 1000 empleados
C13: Entretenimiento | D13: 500 - 1000 empleados
C14: Automotriz | D14: 500 - 1000 empleados
... C17: Service Provider | D17: 200 - 500 empleados
H48: Construccion
H49: Educación
H50: Energia
H51: Transporte y Logistica
H52: Petroleo,Gas y Mineria
H53: Retail
H54: Salud
H55: Tecnologia
H56: Banca
H57: Entretenimiento
H58: Automotriz
H59: Gobierno
... H61: Service Provider

Sheet REVENEW X INDUSTRIAS
A3: Cuenta de EMPRESA | B3: REVENEW | S3: Industria | T3: Revenue máximo | U3: Nivel
A4: INDUSTRIA | B4: 100M-250M | C4: 10M-50M | D4: 1B-10B | E4: 1M-10M | F4: 250M-500M | G4: 500M-1B | H4: 50M-100M | I4: 5M-10M | J4: Total general | S4: Automotriz | T4: 5M–10M | U4: 1
A5: Automotriz | B5: 1 | D5: 1 | F5: 1 | J5: 3 | S5: Construcción | T5: 10M–50M | U5: 2
A6: Banca | C6: 2 | D6: 1 | E6: 1 | H6: 2 | J6: 6 | S6: Educación | T6: 10M–50M | U6: 2
A7: Construccion | D7: 1 | E7: 2 | F7: 3 | H7: 5 | J7: 11 | S7: Gobierno | T7: 10M–50M | U7: 2
A8: Educación | E8: 1 | H8: 1 | J8: 2 | S8: Retail | T8: 10M–50M | U8: 2
A9: Energia | B9: 1 | D9: 1 | J9: 2 | S9: Tecnología | T9: 10M–50M | U9: 2
A10: Entretenimiento | B10: 1 | G10: 1 | H10: 5 | J10: 7 | S10: Transporte_Logística | T10: 10M–50M | U10: 2
A11: Gobierno | E11: 3 | F11: 2 | G11: 1 | H11: 1 | J11: 7 | S11: Entretenimiento | T11: 50M–100M | U11: 3
A12: Manufactura | B12: 9 | C12: 3 | D12: 2 | E12: 3 | F12: 2 | G12: 1 | H12: 16 | I12: 2 | J12: 38 | S12: Salud | T12: 100M–250M | U12: 4
A13: Petroleo_Gas_Mineria | B13: 4 | C13: 1 | D13: 4 | E13: 1 | F13: 3 | H13: 7 | I13: 2 | J13: 22 | S13: Banca | T13: 100M–250M | U13: 4
A14: Retail | E14: 1 | F14: 1 | H14: 2 | J14: 4 | S14: Energía | T14: 250M–500M | U14: 5
A15: Salud | B15: 6 | C15: 1 | E15: 3 | F15: 4 | H15: 3 | J15: 17 | S15: Manufactura | T15: 250M–500M | U15: 5
A16: Service_Provider | B16: 3 | C16: 4 | D16: 1 | E16: 7 | F16: 3 | H16: 10 | J16: 28 | S16: Manufactura_Logística | T16: 500M–1B | U16: 6
A17: Tecnologia | C17: 3 | D17: 1 | E17: 4 | H17: 2 | J17: 10 | S17: Petróleo_Gas_Minería | T17: 1B–10B | U17: 7
A18: Transporte_Logistica | B18: 1 | C18: 3 | E18: 1 | H18: 3 | J18: 8
A19: Total general | B19: 26 | C19: 17 | D19: 12 | E19: 27 | F19: 19 | G19: 3 | H19: 57 | I19: 4 | J19: 165
L25: IDEA:
L26: PRIORIZAR LAS QUE MAYOR REVENEW TENGAN, AGREGAR MAS EMPRESAS DE ESTE TIPO DE INDUSTRIA
L27: MAYOR PROBABILIDAD DE INFRAESTRUCTURA

Sheet Listas
A3: PROVINCIA | B3: (Todas)
A5: SITUACION | B5: Cuenta de SITUACION
A6: Cotizado | B6: 5
A7: No interesado | B7: 19
A8: Prospectando | B8: 229 | O8: MAPA DE C/ EMPRESAS X PROVINCIA | P8: LISTO
A9: Reunion Agendada | B9: 30 | O9: C/ DE CONTACTOS X EMPRESAS
A10: Competencia | B10: 1 | O10: “Revenue máximo por industria” (POTENCIAL MÁXIMO) | P10: LISTO
A11: Total general | B11: 284 | O11: GRAFICAR CANTIDAD DE EMPRESAS X INDUSTRIA Y ACOMPAÑAR CON CUANTO ES EL PROMEDIO DE EMPLEADOS | P11: LISTO
O12: CUALES SON NEW LOGO Y STATUS DE COMPETENCIA | P12: PREGUNTAR PABLO
O13: QUE ACCIÓNES TOMAR? (EVENTOS, CAMPAÑAS, MARKETING) | P13: LISTO
O14: MOSTRAR METODOLOGIAS Y RETROALIMENTACIÓN PARA LA BASE | P14: PREGUNTAR A PABLO
O15: IDEA RANKING DE EMPRESAS CON REVENEW MAS ALTO? | P15: PREGUNTAR A PABLO
O17: RANKEAR EMPRESAS X REVENEWS MAS ALTOS
A22: Cuenta de EMPRESA | B22: SITUACION
A23: PROVINCIA | B23: Competencia | C23: Cotizado | D23: No interesado | E23: Prospectando | F23: Reunion Agendada | G23: TOTA GENERAL
A24: Buenos_Aires | B24: 1 | C24: 1 | E24: 16 | F24: 2 | G24: 20
A25: Cordoba | C25: 1 | D25: 10 | E25: 45 | F25: 9 | G25: 65
A26: La_Pampa | D26: 1 | G26: 1
A27: Mendoza | D27: 1 | E27: 50 | F27: 4 | G27: 55
A28: Neuquen | C28: 1 | D28: 2 | E28: 11 | F28: 5 | G28: 19
A29: Rio_Negro | E29: 3 | F29: 1 | G29: 4
A30: Salta | D30: 3 | E30: 11 | G30: 14
A31: Santa_Fe | C31: 2 | D31: 2 | E31: 62 | F31: 7 | G31: 73
A32: Tucuman | E32: 21 | F32: 2 | G32: 23
A33: La_Rioja | E33: 2 | G33: 2
A34: Entre_Rios | E34: 5 | G34: 5
A35: Santiago_del_Estero | E35: 2 | G35: 2
A36: Santa_Cruz | E36: 1 | G36: 1
A37: TOTA GENERAL | B37: 1 | C37: 5 | D37: 19 | E37: 229 | F37: 30 | G37: 284
B93: EMPRESA | C93: INDUSTRIA | D93: N° DE OPORTUNIDAD | E93: STATUS | F93: MONTO COTIZADO
B94: Barrick Gold | C94: Petroleo_Gas_Mineria | E94: DEVELOPMENT
B95: Prodeman S.A. | C95: Manufactura | D95: JMONT20250403-124897 | E95: LOST | F95: 11480
B96: Aguas Santafesinas S.A. | C96: Gobierno | D96: YHAIM20250901-152660 | E96: LOST | F96: 11880
B97: Electronica Megatone S.A. + Conmega A.C.E. (Musimundo) | C97: Manufactura | D97: JMONT20250714-145066 | E97: DEVELOPMENT | F97: 45000

Sheet Oportunidades
A2: IS | B2: IS | C2: EMPRESA | D2: INDUSTRIA | E2: N° DE OPORTUNIDAD | F2: STATUS | G2: MONTO COTIZADO
A3: Analista 1 | B3: Analista 2 | C3: Suarez S.R.L. | D3: Manufactura | E3: CYLT20251775-238943 | F3: LOST | G3: 11480
A4: Analista 2 | B4: Analista 2 | C4: Paez S.R.L. | D4: Gobierno | E4: ELOK20250531-193972 | F4: LOST | G4: 11880
A5: Analista 2 | B5: Analista 2 | C5: Benitez Ltda. | D5: Retail | E5: OPUW20250303-406024 | F5: DEVELOPMENT | G5: 45000
A6: Analista 2 | B6: Analista 2 | C6: Godoy Group | D6: Gobierno | E6: KUSO20254078-699743 | F6: DEVELOPMENT | G6: 16248
A7: Analista 2 | B7: Analista 1 | C7: Rodriguez S.A.S. | D7: Mineria | E7: REGG20252491-166340 | F7: NO GO | G7: 8000
A12: IS | B12: EMPRESA | C12: Ferreyra S.A.S. | D12: N° DE OPORTUNIDAD | E12: LKMB20254224-358568 | F12: MONTO COTIZADO
A13: Analista 1 | B13: BARRICK GOLD | C13: Gonzalez Argentina | D13: PEST2025 | E13: PFCH20256584-448354
A14: Analista 2 | B14: PRODEMAN | C14: Aguero Internacional | D14: JMONT20250403-124897 | E14: UIIV20260767-723266 | F14: 11480
A15: Analista 2 | B15: AGUAS SANTAFESINAS | C15: Pereyra S.A.S. | D15: YHAIM20250901-152660 | E15: HPSM20253011-517584 | F15: 11880
A16: Analista 2 | B16: CONMEGA | C16: Villalba Ltda. | D16: JMONT2025 | E16: HSMO20254072-441716 | F16: 45000
A17: Analista 2 | B17: AUBASA | C17: Pereyra S.A.S. | D17: JMONT2025 | E17: JVKC20259339-309505 | F17: 16248
B24: MES | C24: Paez S.R.L. | D24: AM | E24: PORO20257664-842776 | F24: NUMERO DE OPP | G24: COMISION

Sheet EMPRESAS MAYOR REVENEW
A1: INDUSTRIA | B1: Manufactura
A3: Cuenta de EMPRESA | B3: REVENEW | C3: PROVINCIA
B4: 100M-250M | G4: Total 100M-250M | H4: 1B-10B | J4: Total 1B-10B | K4: 250M-500M | M4: Total 250M-500M | N4: 500M-1B | O4: Total 500M-1B | P4: 50M-100M | V4: Total 50M-100M | W4: Total general
A5: EMPRESA | B5: Cordoba | C5: Mendoza | D5: Rio_Negro | E5: Salta | F5: Santa_Fe | H5: Mendoza | I5: Santa_Fe | K5: Mendoza | L5: Tucuman | N5: Cordoba | P5: Buenos_Aires | Q5: Cordoba | R5: Mendoza | S5: Rio_Negro | T5: Santa_Fe | U5: Tucuman
A6: Andesmar | K6: 1 | M6: 1 | W6: 1
A7: Argenfruit | R7: 1 | V7: 1 | W7: 1
A8: Bimbo Argentina | N8: 1 | O8: 1 | W8: 1
A9: Bodegas Salentein | R9: 1 | V9: 1 | W9: 1
A10: Catena Zapata | C10: 1 | G10: 1 | W10: 1
A11: Citrusvil - Grupo Lucci | U11: 1 | V11: 1 | W11: 1
A12: Compañía Servicios Farmaceuticos Csf | P12: 1 | V12: 1 | W12: 1
A13: Coprotab - Cooperativa Productora Del Tabaco | E13: 1 | G13: 1 | W13: 1
A14: Electronica Megatone S.A. + Conmega A.C.E. (Musimundo) | F14: 1 | G14: 1 | W14: 1
A15: Expofrut Argentina S. A. | S15: 1 | V15: 1 | W15: 1
A16: Garcia Hnos | T16: 1 | V16: 1 | W16: 1
A17: Grupo Lorenzo | R17: 1 | V17: 1 | W17: 1
A18: ICSA | R18: 1 | V18: 1 | W18: 1
A19: La Coste De Los Andes | R19: 1 | V19: 1 | W19: 1
A20: La Sibila | T20: 1 | V20: 1 | W20: 1
A21: Maniagro Argentina | Q21: 1 | V21: 1 | W21: 1
A22: Molinos | I22: 1 | J22: 1 | W22: 1
A23: Moño Azul S.A. | D23: 1 | G23: 1 | W23: 1
A24: Prodeman S.A. | Q24: 1 | V24: 1 | W24: 1
A25: Systel | P25: 1 | V25: 1 | W25: 1
A26: Tersuave | Q26: 1 | V26: 1 | W26: 1
A27: Verallia | H27: 1 | J27: 1 | W27: 1
A28: Vines Of Mendoza | R28: 1 | V28: 1 | W28: 1
A29: Gitanes | T29: 1 | V29: 1 | W29: 1
A30: Mattievich | F30: 1 | G30: 1 | W30: 1
A31: Porta Hnos | B31: 1 | G31: 1 | W31: 1
A32: Fadea | B32: 1 | G32: 1 | W32: 1
A33: Grupo Disal | B33: 1 | G33: 1 | W33: 1
A34: Maxion Montich | B34: 1 | G34: 1 | W34: 1
A35: Argenti Lemon | L35: 1 | M35: 1 | W35: 1
A36: Total general | B36: 4 | C36: 1 | D36: 1 | E36: 1 | F36: 2 | G36: 9 | H36: 1 | I36: 1 | J36: 2 | K36: 1 | L36: 1 | M36: 2 | N36: 1 | O36: 1 | P36: 2 | Q36: 3 | R36: 6 | S36: 1 | T36: 3 | U36: 1 | V36: 16 | W36: 30

Sheet MEDIDAS NEW LOGO 2026
A4: TEMA NUMEROS DE REUNIONES
C6: DATOS DE PROSPECCIÓN
C7: EMPRESAS NEW LOGO | D7: 280
C8: CONTACTOS EN PROSPECCIÓN | D8: 600
C9: REUNIONES AGENDADAS | D9: 38
C10: COTIZACIÓNES | D10: 6

Sheet LEADS X SF
A1: IS | B1: MES | C1: EMPRESA | D1: URL | E1: COMENTARIO | F1: CALIFICADO
A2: AM2 | B2: Marzo | D2: https://crm.ejemplo.com/lead/60324 | E2: Seguimiento en curso. | F2: NO
A3: AM2 | B3: Marzo | D3: https://crm.ejemplo.com/lead/83607 | E3: Seguimiento en curso. | F3: NO
A4: AM2 | B4: Marzo | D4: https://crm.ejemplo.com/lead/76248 | E4: Seguimiento en curso. | F4: SI
A5: AM2 | B5: Marzo | D5: https://crm.ejemplo.com/lead/95599 | E5: Seguimiento en curso. | F5: SI
A6: AM2 | B6: Marzo | D6: https://crm.ejemplo.com/lead/74876 | E6: Seguimiento en curso. | F6: SI
A7: AM2 | B7: Marzo | D7: https://crm.ejemplo.com/lead/63626 | E7: Seguimiento en curso.
A8: AM1 | B8: Marzo | C8: IMAT
A9: AM1 | B9: Marzo | C9: CASINO MAGIC
A10: AM1 | B10: Marzo | C10: YPFB
A11: AM1 | B11: Marzo | C11: INSAMANI | F11: NO
A12: AM1 | B12: Marzo | C12: BPN
A13: AM1 | B13: Marzo | C13: CASINO DEL RIO
A14: AM1 | B14: Marzo | C14: GYP

Sheet CALLS AA
A1: FECHA | B1: EMPRESA | C1: NOMBRE | D1: PUESTO | E1: EMAIL | F1: TELEFONO | G1: LINKEDIN | H1: COMENTARIO
B2: Vega Corp | C2: Isabella Velazquez Cabrera | D2: Technology Infrastructure Manager | E2: isabella.v@vegacorp.com.ar | F2: +54 9 235 916-5773 | G2: https://www.linkedin.com/in/isabella-velazquez-cabrera-36 | H2: Contacto en proceso.
A3: 46071 | B3: Diaz Group | C3: Mora Julieta Molina | D3: Director de TI | E3: mora.julie@diazgroup.com.ar | F3: +54 9 46 938-7703 | G3: https://www.linkedin.com/in/mora-julieta-molina-98 | H3: Contacto en proceso.
B4: Peralta S.A.S. | C4: Sr(a). Valentino Martinez | D4: Director de Tecnologia | E4: sr(a)..val@peraltasas.com.ar | F4: +54 9 266 242-5961 | G4: https://www.linkedin.com/in/sr(a).-valentino-martinez-96 | H4: Contacto en proceso.
B5: Diaz S.A. | C5: Lara Fausto Ferreyra | D5: CTO | E5: lara.faust@diazsa.com.ar | F5: +54 9 140 774-3525 | G5: https://www.linkedin.com/in/lara-fausto-ferreyra-40 | H5: Contacto en proceso.
B6: Molina Group | C6: Victoria Acosta Cardozo | D6: Gerente de Infraestructura | E6: victoria.a@molinagrou.com.ar | F6: +54 9 204 175-8357 | G6: https://www.linkedin.com/in/victoria-acosta-cardozo-64 | H6: Contacto en proceso.
B7: Correa Argentina | C7: Juan Ignacio Martinez | D7: CTO | E7: juan.ignac@correaarge.com.ar | F7: +54 9 256 696-7566 | G7: https://www.linkedin.com/in/juan-ignacio-martinez-86 | H7: Contacto en proceso.
B8: Romero Internacional | C8: Maximo Julian Aguirre | D8: IT Manager | E8: maximo.jul@romerointe.com.ar | F8: +54 9 270 990-7853 | G8: https://www.linkedin.com/in/maximo-julian-aguirre-78 | H8: Contacto en proceso.
B9: Rivero S.A. | C9: Ian Ezequiel Gomez | D9: Jefe de Infraestructura | E9: ian.ezequi@riverosa.com.ar | F9: +54 9 289 137-6890 | H9: Contacto en proceso.
B10: Muñoz S.R.L. | C10: Sara Moyano | D10: Responsable de Sistemas | F10: +54 9 138 773-6816 | G10: https://www.linkedin.com/in/sara-moyano-23 | H10: Contacto en proceso.
B11: Fernandez Corp | C11: Enzo Benjamin Ortiz Gomez | D11: Administracion de Sistemas | F11: +54 9 33 676-7547 | G11: https://www.linkedin.com/in/enzo-benjamin-ortiz-gomez-31 | H11: Contacto en proceso.
A12: 46076 | B12: Godoy S.R.L. | C12: Lautaro Paz | D12: Encargado de Compras y Contrataciones | E12: lautaro.pa@godoysrl.com.ar | F12: +54 9 231 208-1172 | G12: https://www.linkedin.com/in/lautaro-paz-52 | H12: Contacto en proceso.
A13: 46076 | B13: Diaz Group | C13: Mora Julieta Molina | D13: Director de TI | E13: mora.julie@diazgroup.com.ar | F13: +54 9 143 327-9366 | G13: https://www.linkedin.com/in/mora-julieta-molina-22 | H13: Contacto en proceso.
A14: 46076 | B14: Ponce Group | C14: Maria Emilia Agustin Perez | D14: Coordinador de TI | E14: maria.emil@poncegroup.com.ar | F14: +54 9 296 694-4621 | G14: https://www.linkedin.com/in/maria-emilia-agustin-perez-76 | H14: Contacto en proceso.
A15: 46076 | B15: Flores Internacional | C15: Lisandro Mansilla | D15: Jefa de Compras | E15: lisandro.m@floresinte.com.ar | F15: +54 9 202 500-8586 | G15: https://www.linkedin.com/in/lisandro-mansilla-67 | H15: Contacto en proceso.
A16: 46076 | B16: Garcia Corp | C16: Francisco Diaz Pereyra | D16: Encargado IT | E16: francisco.@garciacorp.com.ar | F16: +54 9 267 254-6651 | G16: https://www.linkedin.com/in/francisco-diaz-pereyra-96 | H16: Contacto en proceso.
A17: 46076 | B17: Garcia Corp | C17: Juan Pablo Lopez | D17: Gerente de Sistemas | E17: juan.pablo@garciacorp.com.ar | F17: +54 9 258 207-5840 | G17: https://www.linkedin.com/in/juan-pablo-lopez-13 | H17: Contacto en proceso.
A18: 46076 | B18: Gomez Group | C18: Thiago Valentin Lorenzo Gomez | D18: Administrador de Infraestructura IT | E18: thiago.val@gomezgroup.com.ar | F18: +54 9 54 218-3321 | G18: https://www.linkedin.com/in/thiago-valentin-lorenzo-gomez-63 | H18: Contacto en proceso.
A19: 46076 | B19: Gomez Group | C19: Ema Valentina Romero | D19: Administrador de Red | E19: ema.valent@gomezgroup.com.ar | F19: +54 9 170 451-8460 | G19: https://www.linkedin.com/in/ema-valentina--romero-54 | H19: Contacto en proceso.
A20: 46076 | B20: Sanchez Group | C20: Geronimo Bianca Gomez | D20: Resposable de Produccion y Tecnologia | F20: +54 9 277 594-6706 | G20: https://www.linkedin.com/in/geronimo-bianca-gomez-36 | H20: Contacto en proceso.
A21: 46076 | B21: Lucero S.R.L. | C21: Emma Morena Sosa | D21: Responsable de Tecnologia | E21: emma.moren@lucerosrl.com.ar | F21: +54 9 60 548-8412 | G21: https://www.linkedin.com/in/emma-morena-sosa-70 | H21: Contacto en proceso.
A22: 46076 | B22: Rodriguez S.R.L. | C22: Santino Benjamin Tomàs Peralta Romero | D22: Jefe de Tecnologia | E22: santino.be@rodriguezs.com.ar | F22: +54 9 45 407-1732 | G22: https://www.linkedin.com/in/santino-benjamin-tomàs-peralta-romero-50 | H22: Contacto en proceso.
A23: 46076 | B23: Coronel Argentina | C23: Tomas Santiago Martinez Castro | D23: Gerente de Compras y Contrataciones | E23: tomas.sant@coronelarg.com.ar | F23: +54 9 22 969-6620 | G23: https://www.linkedin.com/in/tomas-santiago-martinez-castro-24 | H23: Contacto en proceso.
A24: 46076 | B24: Hernandez Corp | C24: Dr(a). Matilda Figueroa | D24: Sistemas | E24: dr(a)..mat@hernandezc.com.ar | F24: +54 9 66 793-3692 | G24: https://www.linkedin.com/in/dr(a).-matilda-figueroa-92 | H24: Contacto en proceso.
A25: 46076 | B25: Ojeda Argentina | C25: Felipe Santiago Hernandez Vazquez | D25: Gerente de Tecnologia | F25: +54 9 275 278-3623 | G25: https://www.linkedin.com/in/felipe-santiago-hernandez-vazquez-41 | H25: Contacto en proceso.
A26: 46076 | B26: Barrios Corp | C26: Alvaro Vera | D26: Gerente de Tecnologia e Innovacion | E26: alvaro.ver@barrioscor.com.ar | F26: +54 9 297 536-8570 | G26: https://www.linkedin.com/in/alvaro-vera-52 | H26: Contacto en proceso.
A27: 46076 | B27: Barrios Corp | C27: Sr(a). Juan Ignacio Navarro | D27: Gerente de Compras | F27: +54 9 218 744-4022 | G27: https://www.linkedin.com/in/sr(a).-juan-ignacio-navarro-39 | H27: Contacto en proceso.
A28: 46076 | B28: Farias S.A. | C28: Renzo Alma Valentina Fernandez | D28: Gerente de Sistemas | F28: +54 9 232 505-1478 | G28: https://www.linkedin.com/in/renzo-alma-valentina-fernandez-33 | H28: Contacto en proceso.
A29: 46076 | B29: Farias S.A. | C29: Sofia Paz | D29: Responsable de Infraestructura y soporte | E29: sofia.paz@fariassa.com.ar | F29: +54 9 112 560-8037 | G29: https://www.linkedin.com/in/sofia-paz-88 | H29: Contacto en proceso.
A30: 46077 | B30: Godoy Corp | C30: Emma Felipe Diaz | D30: Director de Sistemas | E30: emma.felip@godoycorp.com.ar | F30: +54 9 13 821-4519 | G30: https://www.linkedin.com/in/emma-felipe-diaz-59 | H30: Contacto en proceso.
B31: Maldonado S.A. | C31: Sr(a). Federico Sosa | D31: Director de Tecnologia | E31: sr(a)..fed@maldonados.com.ar | F31: +54 9 153 870-2025 | G31: https://www.linkedin.com/in/sr(a).-federico-sosa-36 | H31: Contacto en proceso.
B32: Gomez S.R.L. | C32: Dr(a). Juan Cruz Ojeda | D32: Gerente de Sistemas | E32: dr(a)..jua@gomezsrl.com.ar | F32: +54 9 63 918-9796 | G32: https://www.linkedin.com/in/dr(a).-juan-cruz-ojeda-83 | H32: Contacto en proceso.
B33: Gomez S.R.L. | C33: Francesca Ruiz Romero | D33: Infraestructura Tecnologica | F33: +54 9 198 433-4228 | G33: https://www.linkedin.com/in/francesca-ruiz-romero-33 | H33: Contacto en proceso.
B34: Flores Internacional | C34: Bastian Gonzalez | D34: Comprador | F34: +54 9 69 368-9019 | G34: https://www.linkedin.com/in/bastian-gonzalez-68 | H34: Contacto en proceso.
B35: Perez Corp | C35: Dr(a). Santino Fernandez | D35: Gerente de Sistemas | F35: +54 9 171 711-7367 | G35: https://www.linkedin.com/in/dr(a).-santino-fernandez-77 | H35: Contacto en proceso.
B36: Gonzalez S.A. | C36: Sr(a). Carmela Ortiz | D36: Gerente de Sistemas | E36: sr(a)..car@gonzalezsa.com.ar | F36: +54 9 211 701-2871 | G36: https://www.linkedin.com/in/sr(a).-carmela-ortiz-88 | H36: Contacto en proceso.
B37: Vazquez S.A. | C37: Joaquina Emiliano Lucero Perez | D37: Encargado de IT | E37: joaquina.e@vazquezsa.com.ar | F37: +54 9 191 965-8501 | G37: https://www.linkedin.com/in/joaquina-emiliano-lucero-perez-54 | H37: Contacto en proceso.
B38: Maidana Group | C38: Dr(a). Martina Perez | D38: Encargado de telecomunicaciones | E38: dr(a)..mar@maidanagro.com.ar | F38: +54 9 99 933-5873 | G38: https://www.linkedin.com/in/dr(a).-martina-perez-89 | H38: Contacto en proceso.
B39: Godoy Ltda. | C39: Dr(a). Martina Paez | D39: Responsable de Infraestructura y soporte | F39: +54 9 54 788-3194 | G39: https://www.linkedin.com/in/dr(a).-martina-paez-88 | H39: Contacto en proceso.
A40: 46078 | B40: Pereyra Ltda. | E40: cotac@acueductoscentro.com.ar | F40: +54 9 71 344-6003 | H40: Contacto en proceso.
...

Sheet Target Empresas Franco
A1: TOP 50 PROSPECTOS — FZ (Situación: Prospectando)
A2: Ordenado por probabilidad de contrato · Revenue · Industria · Engagement actual
A3: # | B3: EMPRESA | C3: INDUSTRIA | D3: PROVINCIA | E3: REVENUE | F3: EMPLEADOS | G3: POR QUÉ RANKEA ACÁ | H3: ENGAGEMENT ACTUAL | I3: PRÓXIMO PASO
A4: 1 | B4: Quiroga Argentina | C4: Banca | D4: Córdoba | E4: 1B–10B | F4: 1,000–5,000 | G4: Bancos = contratos OEM masivos y presión regulatoria. 5 contactos mapeados: Director TI, Gte Sistemas, Head of Technical. | H4: En contacto. | I4: Llamada de seguimiento. | J4: listo
A5: 2 | B5: Cabrera S.A.S. | C5: Manufactura | D5: Buenos Aires | E5: Multinacional | F5: Corp. global | G5: Multinacional con datacenter propio y equipo IT grande. Ya entraste por arriba del embudo con el CFO. | H5: En contacto. | I5: Llamada de seguimiento. | J5: listo
A6: 3 | B6: Maidana Ltda. | C6: Manufactura | D6: Córdoba | E6: 500M–1B | F6: 10,000–100,000 | G6: Planta industrial de esa escala = cientos de equipos. CFO refirió al IT Regional. Director Finanzas IC9. | H6: En contacto. | I6: Llamada de seguimiento. | J6: listo
A7: 4 | B7: Gomez Internacional | C7: Manufactura | D7: Santa Fe | E7: 1B–10B | F7: 1,000–5,000 | G7: Revenue altísimo. Industria alimentaria = infraestructura IT/OT crítica. Compras es puerta de entrada a IT. | H7: En contacto. | I7: Llamada de seguimiento. | J7: buscar datos
A8: 5 | B8: Arias Corp | C8: Salud | D8: Buenos Aires | E8: N/D | F8: 5,000–10,000 | G8: Prepaga nacional = servidores propios, equipos críticos 24/7. Líder de Infraestructura IT mapeado. | H8: En contacto. | I8: Llamada de seguimiento. | J8: no prospectar
A9: 6 | B9: Martin S.A. | C9: Petroleo/Gas | D9: Buenos Aires | E9: 1B–10B | F9: 5,000–10,000 | G9: Subsidiaria de Techint. Operaciones críticas con hardware que nadie puede parar. | H9: En contacto. | I9: Llamada de seguimiento. | J9: agregar mas prospectos
A10: 7 | B10: Perez S.A.S. | C10: Salud/Pharma | D10: Buenos Aires | E10: 100M–250M | F10: Global: 10,000+ | G10: Farmacéutica multinacional. Equipos regulados = no pueden operar sin soporte vigente. | H10: En contacto. | I10: Llamada de seguimiento. | J10: agregar mas prospectos
A11: 8 | B11: Gonzalez Internacional | C11: Petroleo/Gas | D11: Neuquén | E11: 250M–500M | F11: 1,000–5,000 | G11: Oil & gas en Neuquén = infraestructura crítica en campo. Manager IT y Coordinador Compras contactados. | H11: En contacto. | I11: Llamada de seguimiento. | J11: listo
A12: 9 | B12: Velazquez Internacional | C12: Service Provider | D12: Córdoba | E12: 1B–10B | F12: 5,000–10,000 | G12: Revenue enorme para un service provider cordobés. Probablemente tienen infraestructura propia importante. | H12: En contacto. | I12: Llamada de seguimiento. | J12: respondio, en call con compras
A13: 10 | B13: Blanco S.A. | C13: Petroleo/Gas | D13: Córdoba | E13: 250M–500M | F13: 500–1,000 | G13: Concesionaria de gas. Equipos SCADA y servidores de operación crítica en tu provincia. | H13: En contacto. | I13: Llamada de seguimiento.
A14: 11 | B14: Lopez Group | C14: Service Provider | D14: Córdoba | E14: 250M–500M | F14: 1,000–5,000 | G14: BPO/contact center con infraestructura propia masiva: servidores, switches y storage para call center. | H14: En contacto. | I14: Llamada de seguimiento.
A15: 12 | B15: Dominguez Argentina | C15: Construcción | D15: Neuquén | E15: 250M–500M | F15: 1,000–5,000 | G15: Ingeniería ligada al oil & gas. Gte Proyectos prometió referir al IT. OP Leader en IC7. | H15: En contacto. | I15: Llamada de seguimiento.
A16: 13 | B16: Rodriguez Argentina | C16: Construcción/Oil | D16: Neuquén | E16: 250M–500M | F16: 1,000–5,000 | G16: Operadora en Vaca Muerta. Hardware industrial en condiciones extremas = garantías vencen rápido. | H16: En contacto. | I16: Llamada de seguimiento.
A17: 14 | B17: Suarez S.A.S. | C17: Automotriz | D17: Córdoba | E17: 250M–500M | F17: 1,000–5,000 | G17: Grupo de concesionarias grande. Manejan ERP, servidores para inventario y financiamiento. | H17: En contacto. | I17: Llamada de seguimiento.
A18: 15 | B18: Perez Argentina | C18: Tecnología | D18: Córdoba | E18: 1B–10B | F18: 50–200 | G18: Revenue enorme para pocos empleados → posible MSP o holding. Puede ser cliente y canal. | H18: En contacto. | I18: Llamada de seguimiento.
A19: 16 | B19: Vargas S.A.S. | C19: Manufactura | D19: Córdoba | E19: 100M–250M | F19: 500–1,000 | G19: El referido interno de finanzas a sistemas ya ocurrió. Falta el contacto IT que lo recibió. | H19: En contacto. | I19: Llamada de seguimiento.
A20: 17 | B20: Godoy Corp | C20: Manufactura | D20: Río Negro | E20: 100M–250M | F20: 1,000–5,000 | G20: Empacadora industrial. Infraestructura de frío + IT de planta. Jefe regresa en abril. | H20: En contacto. | I20: Llamada de seguimiento.
A21: 18 | B21: Martinez Argentina | C21: Manufactura | D21: Tucumán | E21: 50M–100M | F21: 500–1,000 | G21: Jefe de Tecnología ya respondió y nos conocía. Planta citrícola con infraestructura IT y OT. | H21: En contacto. | I21: Llamada de seguimiento.
A22: 19 | B22: Romero S.A.S. | C22: Minería | D22: Salta | E22: 100M–250M | F22: 500–1,000 | G22: Minera aurífera en operación. Equipos en condiciones extremas lejos del soporte OEM. | H22: En contacto. | I22: Llamada de seguimiento.
A23: 20 | B23: Rodriguez S.A.S. | C23: Minería | D23: Salta | E23: 5M–10M | F23: 200–500 | G23: Revenue bajo pero el decisor IT ya respondió. Ciclo de venta más corto. Señal fuerte. | H23: En contacto. | I23: Llamada de seguimiento.
A24: 21 | B24: Farias S.R.L. | C24: Construcción | D24: Córdoba | E24: 1B–10B | F24: 1,000–5,000 | G24: Revenue 1B-10B en construcción = obra grande y sostenida. Probablemente ligada a oil & gas o infraestructura pública. | H24: En contacto. | I24: Llamada de seguimiento.
... A53: 50 | B53: Diaz Corp | C53: Manufactura/Petroquímica | D53: Entre Ríos | E53: N/D | F53: 200–500 | G53: Empresa petroquímica. CTO Mateo Perez contactado IC2 y aceptó. Están en pleno deploy. | H53: En contacto. | I53: Llamada de seguimiento.
